<?xml version='1.0' encoding='utf-8'?>
<robot name="dr_octopus_right">
  <link name="base_link" />
  <link name="link0">
    <visual>
      <origin xyz="0 0 0" rpy="0 0 0" />
      <geometry>
        <mesh filename="package://openarmx_description/meshes/arm/v10/visual/link0.dae" />
      </geometry>
    </visual>
    <collision>
      <origin xyz="0 0 0" rpy="0 0 0" />
      <geometry>
        <mesh filename="package://openarmx_description/meshes/arm/v10/collision/link0_symp.stl" />
      </geometry>
    </collision>
    <inertial>
      <mass value="1.77268" />
      <inertia ixx="0.002463" ixy="0" ixz="0" iyy="0.001962" iyz="0" izz="0.003414" />
    </inertial>
  </link>
  <link name="link1">
    <visual>
      <origin xyz="0 0 0" rpy="0 0 0" />
      <geometry>
        <mesh filename="package://openarmx_description/meshes/arm/v10/visual/link1.dae" />
      </geometry>
    </visual>
    <collision>
      <origin xyz="0 0 0" rpy="0 0 0" />
      <geometry>
        <mesh filename="package://openarmx_description/meshes/arm/v10/collision/link1_symp.stl" />
      </geometry>
    </collision>
    <inertial>
      <mass value="1.688763" />
      <inertia ixx="0.003463" ixy="0" ixz="0" iyy="0.002551" iyz="0" izz="0.001916" />
    </inertial>
  </link>
  <link name="link2">
    <visual>
      <origin xyz="0 0 0" rpy="0 0 0" />
      <geometry>
        <mesh filename="package://openarmx_description/meshes/arm/v10/visual/link2.dae" />
      </geometry>
    </visual>
    <collision>
      <origin xyz="0 0 0" rpy="0 0 0" />
      <geometry>
        <mesh filename="package://openarmx_description/meshes/arm/v10/collision/link2_symp.stl" />
      </geometry>
    </collision>
    <inertial>
      <mass value="0.396704" />
      <inertia ixx="0.000834" ixy="0" ixz="0" iyy="0.000822" iyz="0" izz="0.000385" />
    </inertial>
  </link>
  <link name="link3">
    <visual>
      <origin xyz="0 0 0" rpy="0 0 0" />
      <geometry>
        <mesh filename="package://openarmx_description/meshes/arm/v10/visual/link3.dae" />
      </geometry>
    </visual>
    <collision>
      <origin xyz="0 0 0" rpy="0 0 0" />
      <geometry>
        <mesh filename="package://openarmx_description/meshes/arm/v10/collision/link3_symp.stl" />
      </geometry>
    </collision>
    <inertial>
      <mass value="2.492784" />
      <inertia ixx="0.010352" ixy="0" ixz="0" iyy="0.010343" iyz="0" izz="0.003003" />
    </inertial>
  </link>
  <link name="link4">
    <visual>
      <origin xyz="0 0 0" rpy="0 0 0" />
      <geometry>
        <mesh filename="package://openarmx_description/meshes/arm/v10/visual/link4.dae" />
      </geometry>
    </visual>
    <collision>
      <origin xyz="0 0 0" rpy="0 0 0" />
      <geometry>
        <mesh filename="package://openarmx_description/meshes/arm/v10/collision/link4_symp.stl" />
      </geometry>
    </collision>
    <inertial>
      <mass value="0.779755" />
      <inertia ixx="0.002015" ixy="0" ixz="0" iyy="0.00162" iyz="0" izz="0.000768" />
    </inertial>
  </link>
  <link name="link5">
    <visual>
      <origin xyz="0 0 0" rpy="0 0 0" />
      <geometry>
        <mesh filename="package://openarmx_description/meshes/arm/v10/visual/link5.dae" />
      </geometry>
    </visual>
    <collision>
      <origin xyz="0 0 0" rpy="0 0 0" />
      <geometry>
        <mesh filename="package://openarmx_description/meshes/arm/v10/collision/link5_symp.stl" />
      </geometry>
    </collision>
    <inertial>
      <mass value="0.687255" />
      <inertia ixx="0.000831" ixy="0" ixz="0" iyy="0.001066" iyz="0" izz="0.000496" />
    </inertial>
  </link>
  <link name="link6">
    <visual>
      <origin xyz="0 0 0" rpy="0 0 0" />
      <geometry>
        <mesh filename="package://openarmx_description/meshes/arm/v10/visual/link6.dae" />
      </geometry>
    </visual>
    <collision>
      <origin xyz="0 0 0" rpy="0 0 0" />
      <geometry>
        <mesh filename="package://openarmx_description/meshes/arm/v10/collision/link6_symp.stl" />
      </geometry>
    </collision>
    <inertial>
      <mass value="0.384836" />
      <inertia ixx="0.000292" ixy="0" ixz="0" iyy="0.000276" iyz="0" izz="0.000227" />
    </inertial>
  </link>
  <link name="link7">
    <visual>
      <origin xyz="0 0 0" rpy="0 0 0" />
      <geometry>
        <mesh filename="package://openarmx_description/meshes/arm/v10/visual/link7.dae" />
      </geometry>
    </visual>
    <collision>
      <origin xyz="0 0 0" rpy="0 0 0" />
      <geometry>
        <mesh filename="package://openarmx_description/meshes/arm/v10/collision/link7_symp.stl" />
      </geometry>
    </collision>
    <inertial>
      <mass value="0.624972" />
      <inertia ixx="0.001598" ixy="0" ixz="0" iyy="0.001067" iyz="0" izz="0.000784" />
    </inertial>
  </link>
  <link name="link3_prime">
    <visual>
      <origin xyz="0 0 0" rpy="0 0 0" />
      <geometry>
        <mesh filename="package://openarmx_description/meshes/arm/v10/visual/link3.dae" />
      </geometry>
    </visual>
    <collision>
      <origin xyz="0 0 0" rpy="0 0 0" />
      <geometry>
        <mesh filename="package://openarmx_description/meshes/arm/v10/collision/link3_symp.stl" />
      </geometry>
    </collision>
    <inertial>
      <mass value="2.492784" />
      <inertia ixx="0.010352" ixy="0" ixz="0" iyy="0.010343" iyz="0" izz="0.003003" />
    </inertial>
  </link>
  <link name="link4_prime">
    <visual>
      <origin xyz="0 0 0" rpy="0 0 0" />
      <geometry>
        <mesh filename="package://openarmx_description/meshes/arm/v10/visual/link4.dae" />
      </geometry>
    </visual>
    <collision>
      <origin xyz="0 0 0" rpy="0 0 0" />
      <geometry>
        <mesh filename="package://openarmx_description/meshes/arm/v10/collision/link4_symp.stl" />
      </geometry>
    </collision>
    <inertial>
      <mass value="0.779755" />
      <inertia ixx="0.002015" ixy="0" ixz="0" iyy="0.00162" iyz="0" izz="0.000768" />
    </inertial>
  </link>
  <link name="link4_ext" />
  <link name="link7_pico" />
  <link name="hand">
    <visual>
      <origin xyz="0.0 0.0 -0.6585" rpy="0 0 0" />
      <geometry>
        <mesh filename="package://openarmx_description/meshes/ee/openarmx_hand/visual/hand.dae" scale="0.001 0.001 0.001" />
      </geometry>
    </visual>
    <collision>
      <origin xyz="0.0 0.0 -0.6585" rpy="0 0 0" />
      <geometry>
        <mesh filename="package://openarmx_description/meshes/ee/openarmx_hand/collision/hand.stl" scale="0.001 0.001 0.001" />
      </geometry>
    </collision>
    <inertial>
      <mass value="0.35" />
      <inertia ixx="0.0002473" ixy="0" ixz="0" iyy="1.763e-05" iyz="0" izz="0.0002521" />
    </inertial>
  </link>
  <link name="hand_tcp" />
  <link name="right_finger">
    <visual>
      <origin xyz="0.0 0.05 -0.673001" rpy="0 0 0" />
      <geometry>
        <mesh filename="package://openarmx_description/meshes/ee/openarmx_hand/visual/finger.dae" scale="0.001 -0.001 0.001" />
      </geometry>
    </visual>
    <collision>
      <origin xyz="0.0 0.05 -0.673001" rpy="0 0 0" />
      <geometry>
        <mesh filename="package://openarmx_description/meshes/ee/openarmx_hand/collision/finger.stl" scale="0.001 -0.001 0.001" />
      </geometry>
    </collision>
    <inertial>
      <mass value="0.05" />
      <inertia ixx="0.001" ixy="0" ixz="0" iyy="0.001" iyz="0" izz="0.001" />
    </inertial>
  </link>
  <link name="left_finger">
    <visual>
      <origin xyz="0.0 -0.05 -0.673001" rpy="0 0 0" />
      <geometry>
        <mesh filename="package://openarmx_description/meshes/ee/openarmx_hand/visual/finger.dae" scale="0.001 0.001 0.001" />
      </geometry>
    </visual>
    <collision>
      <origin xyz="0.0 -0.05 -0.673001" rpy="0 0 0" />
      <geometry>
        <mesh filename="package://openarmx_description/meshes/ee/openarmx_hand/collision/finger.stl" scale="0.001 0.001 0.001" />
      </geometry>
    </collision>
    <inertial>
      <mass value="0.05" />
      <inertia ixx="0.001" ixy="0" ixz="0" iyy="0.001" iyz="0" izz="0.001" />
    </inertial>
  </link>
  <joint name="base_joint" type="fixed">
    <parent link="base_link" />
    <child link="link0" />
    <origin xyz="0 -0.031 1.2" rpy="1.5708 0 0" />
  </joint>
  <joint name="joint1" type="revolute">
    <parent link="link0" />
    <child link="link1" />
    <origin xyz="0 0 0.058" rpy="0 0 0" />
    <axis xyz="0 0 1" />
    <limit lower="-1.25" upper="3.0" effort="120" velocity="10.47" />
  </joint>
  <joint name="joint2" type="revolute">
    <parent link="link1" />
    <child link="link2" />
    <origin xyz="-0.0205 0 0.081" rpy="1.5708 0 0" />
    <axis xyz="-1 0 0" />
    <limit lower="-0.1292" upper="3.2708" effort="120" velocity="10.47" />
  </joint>
  <joint name="joint3_prime" type="revolute">
    <parent link="link2" />
    <child link="link3_prime" />
    <origin xyz="0.02 0 0.099" rpy="0 0 0" />
    <axis xyz="0 0 1" />
    <limit lower="-1.57" upper="1.57" effort="60" velocity="10.47" />
  </joint>
  <joint name="joint4_prime" type="revolute">
    <parent link="link3_prime" />
    <child link="link4_prime" />
    <origin xyz="0 0.031002 0.14181" rpy="0 0 0" />
    <axis xyz="0 1 0" />
    <limit lower="0.0" upper="1.8" effort="60" velocity="10.47" />
  </joint>
  <joint name="joint3" type="revolute">
    <parent link="link4_prime" />
    <child link="link3" />
    <origin xyz="-0.02 -0.031 0.082" rpy="0 0 0" />
    <axis xyz="0 0 1" />
    <limit lower="-1.57" upper="1.57" effort="60" velocity="10.47" />
  </joint>
  <joint name="joint4" type="revolute">
    <parent link="link3" />
    <child link="link4" />
    <origin xyz="0 0.031002 0.14181" rpy="0 0 0" />
    <axis xyz="0 1 0" />
    <limit lower="0.0" upper="1.8" effort="60" velocity="10.47" />
  </joint>
  <joint name="joint4_ext" type="fixed">
    <parent link="link4" />
    <child link="link4_ext" />
    <origin xyz="0 0 0" rpy="0 0 0" />
  </joint>
  <joint name="joint5" type="revolute">
    <parent link="link4" />
    <child link="link5" />
    <origin xyz="0 -0.0309 0.126" rpy="0 0 0" />
    <axis xyz="0 0 1" />
    <limit lower="-1.5" upper="1.5" effort="14" velocity="10.47" />
  </joint>
  <joint name="joint6" type="revolute">
    <parent link="link5" />
    <child link="link6" />
    <origin xyz="0.037426 0 0.131" rpy="0 0 0" />
    <axis xyz="1 0 0" />
    <limit lower="-0.75" upper="0.75" effort="14" velocity="10.47" />
  </joint>
  <joint name="joint7" type="revolute">
    <parent link="link6" />
    <child link="link7" />
    <origin xyz="-0.0375 0 0" rpy="0 0 0" />
    <axis xyz="0 1 0" />
    <limit lower="-1.4" upper="1.4" effort="14" velocity="10.47" />
  </joint>
  <joint name="link7_pico_joint" type="fixed">
    <parent link="link7" />
    <child link="link7_pico" />
    <origin xyz="0 0 0" rpy="0 3.1416 4.7124" />
  </joint>
  <joint name="hand_joint" type="fixed">
    <parent link="link7" />
    <child link="hand" />
    <origin xyz="0 0 0.1001" rpy="0 0 0" />
  </joint>
  <joint name="hand_tcp_joint" type="fixed">
    <parent link="hand" />
    <child link="hand_tcp" />
    <origin xyz="0 0 0.08" rpy="0 0 0" />
  </joint>
  <joint name="finger_joint1" type="prismatic">
    <parent link="hand" />
    <child link="right_finger" />
    <origin xyz="0 -0.006 0.015" rpy="0 0 0" />
    <axis xyz="0 -1 0" />
    <limit lower="0.0" upper="0.044" effort="333" velocity="10.0" />
  </joint>
  <joint name="finger_joint2" type="prismatic">
    <parent link="hand" />
    <child link="left_finger" />
    <origin xyz="0 0.006 0.015" rpy="0 0 0" />
    <axis xyz="0 1 0" />
    <limit lower="0.0" upper="0.044" effort="333" velocity="10.0" />
    <mimic joint="finger_joint1" multiplier="1" offset="0" />
  </joint>
</robot>