<?xml version="1.0"?>
<robot name="dr_octopus_right" xmlns:xacro="http://ros.org/wiki/xacro">

  <material name="grey"><color rgba="0.6 0.6 0.6 1.0"/></material>
  <material name="dark"><color rgba="0.3 0.3 0.3 1.0"/></material>

  <link name="base_link"/>

  <link name="link0">
    <visual>
      <origin xyz="0 0 0" rpy="0 0 0"/>
      <geometry><mesh filename="package://dr_octopus_right_description/meshes/link0.stl"/></geometry>
      <material name="grey"/>
    </visual>
    <collision>
      <origin xyz="0 0 0" rpy="0 0 0"/>
      <geometry><mesh filename="package://dr_octopus_right_description/meshes/link0.stl"/></geometry>
    </collision>
    <inertial>
      <mass value="0.5"/>
      <inertia ixx="0.001" ixy="0" ixz="0" iyy="0.001" iyz="0" izz="0.001"/>
    </inertial>
  </link>

  <link name="link1">
    <visual>
      <origin xyz="0 0 0" rpy="0 0 0"/>
      <geometry><mesh filename="package://dr_octopus_right_description/meshes/link1.stl"/></geometry>
      <material name="dark"/>
    </visual>
    <collision>
      <origin xyz="0 0 0" rpy="0 0 0"/>
      <geometry><mesh filename="package://dr_octopus_right_description/meshes/link1.stl"/></geometry>
    </collision>
    <inertial>
      <mass value="0.5"/>
      <inertia ixx="0.001" ixy="0" ixz="0" iyy="0.001" iyz="0" izz="0.001"/>
    </inertial>
  </link>

  <link name="link2">
    <visual>
      <origin xyz="0 0 0" rpy="0 0 0"/>
      <geometry><mesh filename="package://dr_octopus_right_description/meshes/link2.stl"/></geometry>
      <material name="grey"/>
    </visual>
    <collision>
      <origin xyz="0 0 0" rpy="0 0 0"/>
      <geometry><mesh filename="package://dr_octopus_right_description/meshes/link2.stl"/></geometry>
    </collision>
    <inertial>
      <mass value="0.5"/>
      <inertia ixx="0.001" ixy="0" ixz="0" iyy="0.001" iyz="0" izz="0.001"/>
    </inertial>
  </link>

  <link name="link3_prime">
    <visual>
      <origin xyz="0 0 0" rpy="0 0 0"/>
      <geometry><mesh filename="package://dr_octopus_right_description/meshes/link3_prime.stl"/></geometry>
      <material name="dark"/>
    </visual>
    <collision>
      <origin xyz="0 0 0" rpy="0 0 0"/>
      <geometry><mesh filename="package://dr_octopus_right_description/meshes/link3_prime.stl"/></geometry>
    </collision>
    <inertial>
      <mass value="0.5"/>
      <inertia ixx="0.001" ixy="0" ixz="0" iyy="0.001" iyz="0" izz="0.001"/>
    </inertial>
  </link>

  <link name="link4_prime">
    <visual>
      <origin xyz="0 0 0" rpy="0 0 0"/>
      <geometry><mesh filename="package://dr_octopus_right_description/meshes/link4_prime.stl"/></geometry>
      <material name="grey"/>
    </visual>
    <collision>
      <origin xyz="0 0 0" rpy="0 0 0"/>
      <geometry><mesh filename="package://dr_octopus_right_description/meshes/link4_prime.stl"/></geometry>
    </collision>
    <inertial>
      <mass value="0.5"/>
      <inertia ixx="0.001" ixy="0" ixz="0" iyy="0.001" iyz="0" izz="0.001"/>
    </inertial>
  </link>

  <link name="link3">
    <visual>
      <origin xyz="0 0 0" rpy="0 0 0"/>
      <geometry><mesh filename="package://dr_octopus_right_description/meshes/link3.stl"/></geometry>
      <material name="dark"/>
    </visual>
    <collision>
      <origin xyz="0 0 0" rpy="0 0 0"/>
      <geometry><mesh filename="package://dr_octopus_right_description/meshes/link3.stl"/></geometry>
    </collision>
    <inertial>
      <mass value="0.5"/>
      <inertia ixx="0.001" ixy="0" ixz="0" iyy="0.001" iyz="0" izz="0.001"/>
    </inertial>
  </link>

  <link name="link4">
    <visual>
      <origin xyz="0 0 0" rpy="0 0 0"/>
      <geometry><mesh filename="package://dr_octopus_right_description/meshes/link4.stl"/></geometry>
      <material name="grey"/>
    </visual>
    <collision>
      <origin xyz="0 0 0" rpy="0 0 0"/>
      <geometry><mesh filename="package://dr_octopus_right_description/meshes/link4.stl"/></geometry>
    </collision>
    <inertial>
      <mass value="0.5"/>
      <inertia ixx="0.001" ixy="0" ixz="0" iyy="0.001" iyz="0" izz="0.001"/>
    </inertial>
  </link>

  <link name="link5">
    <visual>
      <origin xyz="0 0 0" rpy="0 0 0"/>
      <geometry><mesh filename="package://dr_octopus_right_description/meshes/link5.stl"/></geometry>
      <material name="dark"/>
    </visual>
    <collision>
      <origin xyz="0 0 0" rpy="0 0 0"/>
      <geometry><mesh filename="package://dr_octopus_right_description/meshes/link5.stl"/></geometry>
    </collision>
    <inertial>
      <mass value="0.5"/>
      <inertia ixx="0.001" ixy="0" ixz="0" iyy="0.001" iyz="0" izz="0.001"/>
    </inertial>
  </link>

  <link name="link6">
    <visual>
      <origin xyz="0 0 0" rpy="0 0 0"/>
      <geometry><mesh filename="package://dr_octopus_right_description/meshes/link6.stl"/></geometry>
      <material name="grey"/>
    </visual>
    <collision>
      <origin xyz="0 0 0" rpy="0 0 0"/>
      <geometry><mesh filename="package://dr_octopus_right_description/meshes/link6.stl"/></geometry>
    </collision>
    <inertial>
      <mass value="0.5"/>
      <inertia ixx="0.001" ixy="0" ixz="0" iyy="0.001" iyz="0" izz="0.001"/>
    </inertial>
  </link>

  <link name="link7">
    <visual>
      <origin xyz="0 0 0" rpy="0 0 0"/>
      <geometry><mesh filename="package://dr_octopus_right_description/meshes/link7.stl"/></geometry>
      <material name="dark"/>
    </visual>
    <collision>
      <origin xyz="0 0 0" rpy="0 0 0"/>
      <geometry><mesh filename="package://dr_octopus_right_description/meshes/link7.stl"/></geometry>
    </collision>
    <inertial>
      <mass value="0.5"/>
      <inertia ixx="0.001" ixy="0" ixz="0" iyy="0.001" iyz="0" izz="0.001"/>
    </inertial>
  </link>

  <link name="ee">
    <visual>
      <origin xyz="0 0 0" rpy="0 0 0"/>
      <geometry><mesh filename="package://dr_octopus_right_description/meshes/ee.stl"/></geometry>
      <material name="grey"/>
    </visual>
    <collision>
      <origin xyz="0 0 0" rpy="0 0 0"/>
      <geometry><mesh filename="package://dr_octopus_right_description/meshes/ee.stl"/></geometry>
    </collision>
    <inertial>
      <mass value="0.5"/>
      <inertia ixx="0.001" ixy="0" ixz="0" iyy="0.001" iyz="0" izz="0.001"/>
    </inertial>
  </link>

  <joint name="base_joint" type="fixed">
    <parent link="base_link"/>
    <child link="link0"/>
    <origin xyz="-0.010472 -0.263107 0.501182" rpy="0 0 0"/>
  </joint>

  <joint name="joint1" type="revolute">
    <parent link="link0"/>
    <child link="link1"/>
    <origin xyz="0.000000 0.000000 0.019000" rpy="0 0 0"/>
    <axis xyz="0 1 0"/>
    <limit lower="-1.25" upper="3.0" effort="120" velocity="10.47"/>
  </joint>

  <joint name="joint2" type="revolute">
    <parent link="link1"/>
    <child link="link2"/>
    <origin xyz="-0.000001 0.121000 0.000000" rpy="0 0 0"/>
    <axis xyz="0 0 1"/>
    <limit lower="-0.129" upper="3.271" effort="120" velocity="10.47"/>
  </joint>

  <joint name="joint3_prime" type="revolute">
    <parent link="link2"/>
    <child link="link3_prime"/>
    <origin xyz="0.000001 0.101500 -0.000501" rpy="0 0 0"/>
    <axis xyz="0 1 0"/>
    <limit lower="-1.57" upper="1.57" effort="60" velocity="10.47"/>
  </joint>

  <joint name="joint4_prime" type="revolute">
    <parent link="link3_prime"/>
    <child link="link4_prime"/>
    <origin xyz="0.028502 0.139312 0.000000" rpy="0 0 0"/>
    <axis xyz="1 0 0"/>
    <limit lower="0.0" upper="1.8" effort="60" velocity="10.47"/>
  </joint>

  <joint name="joint3" type="revolute">
    <parent link="link4_prime"/>
    <child link="link3"/>
    <origin xyz="-0.028399 0.082687 0.034250" rpy="0 0 0"/>
    <axis xyz="0 1 0"/>
    <limit lower="-1.57" upper="1.57" effort="60" velocity="10.47"/>
  </joint>

  <joint name="joint4" type="revolute">
    <parent link="link3"/>
    <child link="link4"/>
    <origin xyz="0.028502 0.128708 0.053312" rpy="0 0 0"/>
    <axis xyz="1 0 0"/>
    <limit lower="0.0" upper="1.8" effort="60" velocity="10.47"/>
  </joint>

  <joint name="joint5" type="revolute">
    <parent link="link4"/>
    <child link="link5"/>
    <origin xyz="0.008810 0.117794 0.048792" rpy="0 0 0"/>
    <axis xyz="0 1 0"/>
    <limit lower="-1.5" upper="1.5" effort="14" velocity="10.47"/>
  </joint>

  <joint name="joint6" type="revolute">
    <parent link="link5"/>
    <child link="link6"/>
    <origin xyz="-0.037210 0.043422 0.017986" rpy="0 0 0"/>
    <axis xyz="0 0 1"/>
    <limit lower="-0.75" upper="0.75" effort="14" velocity="10.47"/>
  </joint>

  <joint name="joint7" type="revolute">
    <parent link="link6"/>
    <child link="link7"/>
    <origin xyz="-0.031500 0.076108 0.031850" rpy="0 0 0"/>
    <axis xyz="1 0 0"/>
    <limit lower="-1.4" upper="1.4" effort="14" velocity="10.47"/>
  </joint>

  <joint name="joint_ee" type="prismatic">
    <parent link="link7"/>
    <child link="ee"/>
    <origin xyz="0.031499 0.054047 0.022388" rpy="0 0 0"/>
    <axis xyz="0 0 1"/>
    <limit lower="0.0" upper="0.044" effort="333" velocity="10.0"/>
  </joint>

</robot>
