<?xml version='1.0' encoding='utf-8'?>
<robot name="dr_octopus">
  <link name="base_link" />
  <link name="r_link0">
    <visual>
      <origin xyz="0 0 0" rpy="0 0 0" />
      <geometry>
        <mesh filename="package://dr_octopus_description/meshes/arm/v10/visual/link0.dae" />
      </geometry>
    </visual>
    <collision>
      <origin xyz="0 0 0" rpy="0 0 0" />
      <geometry>
        <mesh filename="package://dr_octopus_description/meshes/arm/v10/collision/link0_symp.stl" />
      </geometry>
    </collision>
    <inertial>
      <mass value="1.77268" />
      <inertia ixx="0.002463" ixy="0" ixz="0" iyy="0.001962" iyz="0" izz="0.003414" />
    </inertial>
  </link>
  <link name="r_link1">
    <visual>
      <origin xyz="0 0 0" rpy="0 0 0" />
      <geometry>
        <mesh filename="package://dr_octopus_description/meshes/arm/v10/visual/link1.dae" />
      </geometry>
    </visual>
    <collision>
      <origin xyz="0 0 0" rpy="0 0 0" />
      <geometry>
        <mesh filename="package://dr_octopus_description/meshes/arm/v10/collision/link1_symp.stl" />
      </geometry>
    </collision>
    <inertial>
      <mass value="1.688763" />
      <inertia ixx="0.003463" ixy="0" ixz="0" iyy="0.002551" iyz="0" izz="0.001916" />
    </inertial>
  </link>
  <link name="r_link2">
    <visual>
      <origin xyz="0 0 0" rpy="0 0 0" />
      <geometry>
        <mesh filename="package://dr_octopus_description/meshes/arm/v10/visual/link2.dae" />
      </geometry>
    </visual>
    <collision>
      <origin xyz="0 0 0" rpy="0 0 0" />
      <geometry>
        <mesh filename="package://dr_octopus_description/meshes/arm/v10/collision/link2_symp.stl" />
      </geometry>
    </collision>
    <inertial>
      <mass value="0.396704" />
      <inertia ixx="0.000834" ixy="0" ixz="0" iyy="0.000822" iyz="0" izz="0.000385" />
    </inertial>
  </link>
  <link name="r_link3">
    <visual>
      <origin xyz="0 0 0" rpy="0 0 0" />
      <geometry>
        <mesh filename="package://dr_octopus_description/meshes/arm/v10/visual/link3.dae" />
      </geometry>
    </visual>
    <collision>
      <origin xyz="0 0 0" rpy="0 0 0" />
      <geometry>
        <mesh filename="package://dr_octopus_description/meshes/arm/v10/collision/link3_symp.stl" />
      </geometry>
    </collision>
    <inertial>
      <mass value="2.492784" />
      <inertia ixx="0.010352" ixy="0" ixz="0" iyy="0.010343" iyz="0" izz="0.003003" />
    </inertial>
  </link>
  <link name="r_link4">
    <visual>
      <origin xyz="0 0 0" rpy="0 0 0" />
      <geometry>
        <mesh filename="package://dr_octopus_description/meshes/arm/v10/visual/link4.dae" />
      </geometry>
    </visual>
    <collision>
      <origin xyz="0 0 0" rpy="0 0 0" />
      <geometry>
        <mesh filename="package://dr_octopus_description/meshes/arm/v10/collision/link4_symp.stl" />
      </geometry>
    </collision>
    <inertial>
      <mass value="0.779755" />
      <inertia ixx="0.002015" ixy="0" ixz="0" iyy="0.00162" iyz="0" izz="0.000768" />
    </inertial>
  </link>
  <link name="r_link5">
    <visual>
      <origin xyz="0 0 0" rpy="0 0 0" />
      <geometry>
        <mesh filename="package://dr_octopus_description/meshes/arm/v10/visual/link5.dae" />
      </geometry>
    </visual>
    <collision>
      <origin xyz="0 0 0" rpy="0 0 0" />
      <geometry>
        <mesh filename="package://dr_octopus_description/meshes/arm/v10/collision/link5_symp.stl" />
      </geometry>
    </collision>
    <inertial>
      <mass value="0.687255" />
      <inertia ixx="0.000831" ixy="0" ixz="0" iyy="0.001066" iyz="0" izz="0.000496" />
    </inertial>
  </link>
  <link name="r_link6">
    <visual>
      <origin xyz="0 0 0" rpy="0 0 0" />
      <geometry>
        <mesh filename="package://dr_octopus_description/meshes/arm/v10/visual/link6.dae" />
      </geometry>
    </visual>
    <collision>
      <origin xyz="0 0 0" rpy="0 0 0" />
      <geometry>
        <mesh filename="package://dr_octopus_description/meshes/arm/v10/collision/link6_symp.stl" />
      </geometry>
    </collision>
    <inertial>
      <mass value="0.384836" />
      <inertia ixx="0.000292" ixy="0" ixz="0" iyy="0.000276" iyz="0" izz="0.000227" />
    </inertial>
  </link>
  <link name="r_link7">
    <visual>
      <origin xyz="0 0 0" rpy="0 0 0" />
      <geometry>
        <mesh filename="package://dr_octopus_description/meshes/arm/v10/visual/link7.dae" />
      </geometry>
    </visual>
    <collision>
      <origin xyz="0 0 0" rpy="0 0 0" />
      <geometry>
        <mesh filename="package://dr_octopus_description/meshes/arm/v10/collision/link7_symp.stl" />
      </geometry>
    </collision>
    <inertial>
      <mass value="0.624972" />
      <inertia ixx="0.001598" ixy="0" ixz="0" iyy="0.001067" iyz="0" izz="0.000784" />
    </inertial>
  </link>
  <link name="r_link3_prime">
    <visual>
      <origin xyz="0 0 0" rpy="0 0 0" />
      <geometry>
        <mesh filename="package://dr_octopus_description/meshes/arm/v10/visual/link3.dae" />
      </geometry>
    </visual>
    <collision>
      <origin xyz="0 0 0" rpy="0 0 0" />
      <geometry>
        <mesh filename="package://dr_octopus_description/meshes/arm/v10/collision/link3_symp.stl" />
      </geometry>
    </collision>
    <inertial>
      <mass value="2.492784" />
      <inertia ixx="0.010352" ixy="0" ixz="0" iyy="0.010343" iyz="0" izz="0.003003" />
    </inertial>
  </link>
  <link name="r_link4_prime">
    <visual>
      <origin xyz="0 0 0" rpy="0 0 0" />
      <geometry>
        <mesh filename="package://dr_octopus_description/meshes/arm/v10/visual/link4.dae" />
      </geometry>
    </visual>
    <collision>
      <origin xyz="0 0 0" rpy="0 0 0" />
      <geometry>
        <mesh filename="package://dr_octopus_description/meshes/arm/v10/collision/link4_symp.stl" />
      </geometry>
    </collision>
    <inertial>
      <mass value="0.779755" />
      <inertia ixx="0.002015" ixy="0" ixz="0" iyy="0.00162" iyz="0" izz="0.000768" />
    </inertial>
  </link>
  <link name="r_link4_ext" />
  <link name="r_link7_pico" />
  <link name="r_hand">
    <visual>
      <origin xyz="0.0 0.0 -0.6585" rpy="0 0 0" />
      <geometry>
        <mesh filename="package://dr_octopus_description/meshes/ee/openarmx_hand/visual/hand.dae" scale="0.001 0.001 0.001" />
      </geometry>
    </visual>
    <collision>
      <origin xyz="0.0 0.0 -0.6585" rpy="0 0 0" />
      <geometry>
        <mesh filename="package://dr_octopus_description/meshes/ee/openarmx_hand/collision/hand.stl" scale="0.001 0.001 0.001" />
      </geometry>
    </collision>
    <inertial>
      <mass value="0.35" />
      <inertia ixx="0.0002473" ixy="0" ixz="0" iyy="1.763e-05" iyz="0" izz="0.0002521" />
    </inertial>
  </link>
  <link name="r_hand_tcp" />
  <link name="r_right_finger">
    <visual>
      <origin xyz="0.0 0.05 -0.673001" rpy="0 0 0" />
      <geometry>
        <mesh filename="package://dr_octopus_description/meshes/ee/openarmx_hand/visual/finger.dae" scale="0.001 -0.001 0.001" />
      </geometry>
    </visual>
    <collision>
      <origin xyz="0.0 0.05 -0.673001" rpy="0 0 0" />
      <geometry>
        <mesh filename="package://dr_octopus_description/meshes/ee/openarmx_hand/collision/finger.stl" scale="0.001 -0.001 0.001" />
      </geometry>
    </collision>
    <inertial>
      <mass value="0.036" />
      <inertia ixx="2.375e-06" ixy="0" ixz="0" iyy="2.375e-06" iyz="0" izz="7.5e-07" />
    </inertial>
  </link>
  <link name="r_left_finger">
    <visual>
      <origin xyz="0.0 -0.05 -0.673001" rpy="0 0 0" />
      <geometry>
        <mesh filename="package://dr_octopus_description/meshes/ee/openarmx_hand/visual/finger.dae" scale="0.001 0.001 0.001" />
      </geometry>
    </visual>
    <collision>
      <origin xyz="0.0 -0.05 -0.673001" rpy="0 0 0" />
      <geometry>
        <mesh filename="package://dr_octopus_description/meshes/ee/openarmx_hand/collision/finger.stl" scale="0.001 0.001 0.001" />
      </geometry>
    </collision>
    <inertial>
      <mass value="0.036" />
      <inertia ixx="2.375e-06" ixy="0" ixz="0" iyy="2.375e-06" iyz="0" izz="7.5e-07" />
    </inertial>
  </link>
  <joint name="r_base_joint" type="fixed">
    <parent link="base_link" />
    <child link="r_link0" />
    <origin xyz="0 -0.031 1.2" rpy="1.5708 0 0" />
  </joint>
  <joint name="r_joint1" type="revolute">
    <parent link="r_link0" />
    <child link="r_link1" />
    <origin xyz="0 0 0.058" rpy="0 0 0" />
    <axis xyz="0 0 1" />
    <limit lower="-1.25" upper="3.0" effort="120" velocity="10.47" />
  </joint>
  <joint name="r_joint2" type="revolute">
    <parent link="r_link1" />
    <child link="r_link2" />
    <origin xyz="-0.0205 0 0.081" rpy="1.5708 0 0" />
    <axis xyz="-1 0 0" />
    <limit lower="-0.1292" upper="3.2708" effort="120" velocity="10.47" />
  </joint>
  <joint name="r_joint3_prime" type="revolute">
    <parent link="r_link2" />
    <child link="r_link3_prime" />
    <origin xyz="0.02 0 0.099" rpy="0 0 0" />
    <axis xyz="0 0 1" />
    <limit lower="-1.57" upper="1.57" effort="60" velocity="10.47" />
  </joint>
  <joint name="r_joint4_prime" type="revolute">
    <parent link="r_link3_prime" />
    <child link="r_link4_prime" />
    <origin xyz="0 0.031002 0.14181" rpy="0 0 0" />
    <axis xyz="0 1 0" />
    <limit lower="0.0" upper="1.8" effort="60" velocity="10.47" />
  </joint>
  <joint name="r_joint3" type="revolute">
    <parent link="r_link4_prime" />
    <child link="r_link3" />
    <origin xyz="-0.02 -0.031 0.082" rpy="0 0 0" />
    <axis xyz="0 0 1" />
    <limit lower="-1.57" upper="1.57" effort="60" velocity="10.47" />
  </joint>
  <joint name="r_joint4" type="revolute">
    <parent link="r_link3" />
    <child link="r_link4" />
    <origin xyz="0 0.031002 0.14181" rpy="0 0 0" />
    <axis xyz="0 1 0" />
    <limit lower="0.0" upper="1.8" effort="60" velocity="10.47" />
  </joint>
  <joint name="r_joint4_ext" type="fixed">
    <parent link="r_link4" />
    <child link="r_link4_ext" />
    <origin xyz="0 0 0" rpy="0 0 0" />
  </joint>
  <joint name="r_joint5" type="revolute">
    <parent link="r_link4" />
    <child link="r_link5" />
    <origin xyz="0 -0.0309 0.126" rpy="0 0 0" />
    <axis xyz="0 0 1" />
    <limit lower="-1.5" upper="1.5" effort="14" velocity="10.47" />
  </joint>
  <joint name="r_joint6" type="revolute">
    <parent link="r_link5" />
    <child link="r_link6" />
    <origin xyz="0.037426 0 0.131" rpy="0 0 0" />
    <axis xyz="1 0 0" />
    <limit lower="-0.75" upper="0.75" effort="14" velocity="10.47" />
  </joint>
  <joint name="r_joint7" type="revolute">
    <parent link="r_link6" />
    <child link="r_link7" />
    <origin xyz="-0.0375 0 0" rpy="0 0 0" />
    <axis xyz="0 1 0" />
    <limit lower="-1.4" upper="1.4" effort="14" velocity="10.47" />
  </joint>
  <joint name="r_link7_pico_joint" type="fixed">
    <parent link="r_link7" />
    <child link="r_link7_pico" />
    <origin xyz="0 0 0" rpy="0 3.1416 4.7124" />
  </joint>
  <joint name="r_hand_joint" type="fixed">
    <parent link="r_link7" />
    <child link="r_hand" />
    <origin xyz="0 0 0.1001" rpy="0 0 0" />
  </joint>
  <joint name="r_hand_tcp_joint" type="fixed">
    <parent link="r_hand" />
    <child link="r_hand_tcp" />
    <origin xyz="0 0 0.08" rpy="0 0 0" />
  </joint>
  <joint name="r_finger_joint1" type="prismatic">
    <parent link="r_hand" />
    <child link="r_right_finger" />
    <origin xyz="0 -0.006 0.015" rpy="0 0 0" />
    <axis xyz="0 -1 0" />
    <limit lower="0.0" upper="0.044" effort="333" velocity="10.0" />
  </joint>
  <joint name="r_finger_joint2" type="prismatic">
    <parent link="r_hand" />
    <child link="r_left_finger" />
    <origin xyz="0 0.006 0.015" rpy="0 0 0" />
    <axis xyz="0 1 0" />
    <limit lower="0.0" upper="0.044" effort="333" velocity="10.0" />
    <mimic joint="r_finger_joint1" multiplier="1" offset="0" />
  </joint>
  <link name="l_link0">
    <visual>
      <origin xyz="0 0 0" rpy="0 0 0" />
      <geometry>
        <mesh filename="package://dr_octopus_description/meshes/arm/v10/visual/link0.dae" scale="1.0 -1.0 1.0" />
      </geometry>
    </visual>
    <collision>
      <origin xyz="0 0 0" rpy="0 0 0" />
      <geometry>
        <mesh filename="package://dr_octopus_description/meshes/arm/v10/collision/link0_symp.stl" scale="1.0 -1.0 1.0" />
      </geometry>
    </collision>
    <inertial>
      <mass value="1.77268" />
      <inertia ixx="0.002463" ixy="0" ixz="0" iyy="0.001962" iyz="0" izz="0.003414" />
    </inertial>
  </link>
  <link name="l_link1">
    <visual>
      <origin xyz="0 0 0" rpy="0 0 0" />
      <geometry>
        <mesh filename="package://dr_octopus_description/meshes/arm/v10/visual/link1.dae" scale="1.0 -1.0 1.0" />
      </geometry>
    </visual>
    <collision>
      <origin xyz="0 0 0" rpy="0 0 0" />
      <geometry>
        <mesh filename="package://dr_octopus_description/meshes/arm/v10/collision/link1_symp.stl" scale="1.0 -1.0 1.0" />
      </geometry>
    </collision>
    <inertial>
      <mass value="1.688763" />
      <inertia ixx="0.003463" ixy="0" ixz="0" iyy="0.002551" iyz="0" izz="0.001916" />
    </inertial>
  </link>
  <link name="l_link2">
    <visual>
      <origin xyz="0 0 0" rpy="0 0 0" />
      <geometry>
        <mesh filename="package://dr_octopus_description/meshes/arm/v10/visual/link2.dae" scale="1.0 -1.0 1.0" />
      </geometry>
    </visual>
    <collision>
      <origin xyz="0 0 0" rpy="0 0 0" />
      <geometry>
        <mesh filename="package://dr_octopus_description/meshes/arm/v10/collision/link2_symp.stl" scale="1.0 -1.0 1.0" />
      </geometry>
    </collision>
    <inertial>
      <mass value="0.396704" />
      <inertia ixx="0.000834" ixy="0" ixz="0" iyy="0.000822" iyz="0" izz="0.000385" />
    </inertial>
  </link>
  <link name="l_link3">
    <visual>
      <origin xyz="0 0 0" rpy="0 0 0" />
      <geometry>
        <mesh filename="package://dr_octopus_description/meshes/arm/v10/visual/link3.dae" scale="1.0 -1.0 1.0" />
      </geometry>
    </visual>
    <collision>
      <origin xyz="0 0 0" rpy="0 0 0" />
      <geometry>
        <mesh filename="package://dr_octopus_description/meshes/arm/v10/collision/link3_symp.stl" scale="1.0 -1.0 1.0" />
      </geometry>
    </collision>
    <inertial>
      <mass value="2.492784" />
      <inertia ixx="0.010352" ixy="0" ixz="0" iyy="0.010343" iyz="0" izz="0.003003" />
    </inertial>
  </link>
  <link name="l_link4">
    <visual>
      <origin xyz="0 0 0" rpy="0 0 0" />
      <geometry>
        <mesh filename="package://dr_octopus_description/meshes/arm/v10/visual/link4.dae" scale="1.0 1.0 1.0" />
      </geometry>
    </visual>
    <collision>
      <origin xyz="0 0 0" rpy="0 0 0" />
      <geometry>
        <mesh filename="package://dr_octopus_description/meshes/arm/v10/collision/link4_symp.stl" scale="1.0 1.0 1.0" />
      </geometry>
    </collision>
    <inertial>
      <mass value="0.779755" />
      <inertia ixx="0.002015" ixy="0" ixz="0" iyy="0.00162" iyz="0" izz="0.000768" />
    </inertial>
  </link>
  <link name="l_link5">
    <visual>
      <origin xyz="0 0 0" rpy="0 0 0" />
      <geometry>
        <mesh filename="package://dr_octopus_description/meshes/arm/v10/visual/link5.dae" scale="1.0 -1.0 1.0" />
      </geometry>
    </visual>
    <collision>
      <origin xyz="0 0 0" rpy="0 0 0" />
      <geometry>
        <mesh filename="package://dr_octopus_description/meshes/arm/v10/collision/link5_symp.stl" scale="1.0 -1.0 1.0" />
      </geometry>
    </collision>
    <inertial>
      <mass value="0.687255" />
      <inertia ixx="0.000831" ixy="0" ixz="0" iyy="0.001066" iyz="0" izz="0.000496" />
    </inertial>
  </link>
  <link name="l_link6">
    <visual>
      <origin xyz="0 0 0" rpy="0 0 0" />
      <geometry>
        <mesh filename="package://dr_octopus_description/meshes/arm/v10/visual/link6.dae" scale="1.0 -1.0 1.0" />
      </geometry>
    </visual>
    <collision>
      <origin xyz="0 0 0" rpy="0 0 0" />
      <geometry>
        <mesh filename="package://dr_octopus_description/meshes/arm/v10/collision/link6_symp.stl" scale="1.0 -1.0 1.0" />
      </geometry>
    </collision>
    <inertial>
      <mass value="0.384836" />
      <inertia ixx="0.000292" ixy="0" ixz="0" iyy="0.000276" iyz="0" izz="0.000227" />
    </inertial>
  </link>
  <link name="l_link7">
    <visual>
      <origin xyz="0 0 0" rpy="0 0 0" />
      <geometry>
        <mesh filename="package://dr_octopus_description/meshes/arm/v10/visual/link7.dae" scale="1.0 -1.0 1.0" />
      </geometry>
    </visual>
    <collision>
      <origin xyz="0 0 0" rpy="0 0 0" />
      <geometry>
        <mesh filename="package://dr_octopus_description/meshes/arm/v10/collision/link7_symp.stl" scale="1.0 -1.0 1.0" />
      </geometry>
    </collision>
    <inertial>
      <mass value="0.624972" />
      <inertia ixx="0.001598" ixy="0" ixz="0" iyy="0.001067" iyz="0" izz="0.000784" />
    </inertial>
  </link>
  <link name="l_link3_prime">
    <visual>
      <origin xyz="0 0 0" rpy="0 0 0" />
      <geometry>
        <mesh filename="package://dr_octopus_description/meshes/arm/v10/visual/link3.dae" scale="1.0 -1.0 1.0" />
      </geometry>
    </visual>
    <collision>
      <origin xyz="0 0 0" rpy="0 0 0" />
      <geometry>
        <mesh filename="package://dr_octopus_description/meshes/arm/v10/collision/link3_symp.stl" scale="1.0 -1.0 1.0" />
      </geometry>
    </collision>
    <inertial>
      <mass value="2.492784" />
      <inertia ixx="0.010352" ixy="0" ixz="0" iyy="0.010343" iyz="0" izz="0.003003" />
    </inertial>
  </link>
  <link name="l_link4_prime">
    <visual>
      <origin xyz="0 0 0" rpy="0 0 0" />
      <geometry>
        <mesh filename="package://dr_octopus_description/meshes/arm/v10/visual/link4.dae" scale="1.0 1.0 1.0" />
      </geometry>
    </visual>
    <collision>
      <origin xyz="0 0 0" rpy="0 0 0" />
      <geometry>
        <mesh filename="package://dr_octopus_description/meshes/arm/v10/collision/link4_symp.stl" scale="1.0 1.0 1.0" />
      </geometry>
    </collision>
    <inertial>
      <mass value="0.779755" />
      <inertia ixx="0.002015" ixy="0" ixz="0" iyy="0.00162" iyz="0" izz="0.000768" />
    </inertial>
  </link>
  <link name="l_link4_ext" />
  <link name="l_link7_pico" />
  <link name="l_hand">
    <visual>
      <origin xyz="0.0 0.0 -0.6585" rpy="0 0 0" />
      <geometry>
        <mesh filename="package://dr_octopus_description/meshes/ee/openarmx_hand/visual/hand.dae" scale="0.001 0.001 0.001" />
      </geometry>
    </visual>
    <collision>
      <origin xyz="0.0 0.0 -0.6585" rpy="0 0 0" />
      <geometry>
        <mesh filename="package://dr_octopus_description/meshes/ee/openarmx_hand/collision/hand.stl" scale="0.001 0.001 0.001" />
      </geometry>
    </collision>
    <inertial>
      <mass value="0.35" />
      <inertia ixx="0.0002473" ixy="0" ixz="0" iyy="1.763e-05" iyz="0" izz="0.0002521" />
    </inertial>
  </link>
  <link name="l_hand_tcp" />
  <link name="l_right_finger">
    <visual>
      <origin xyz="0.0 0.05 -0.673001" rpy="0 0 0" />
      <geometry>
        <mesh filename="package://dr_octopus_description/meshes/ee/openarmx_hand/visual/finger.dae" scale="0.001 -0.001 0.001" />
      </geometry>
    </visual>
    <collision>
      <origin xyz="0.0 0.05 -0.673001" rpy="0 0 0" />
      <geometry>
        <mesh filename="package://dr_octopus_description/meshes/ee/openarmx_hand/collision/finger.stl" scale="0.001 -0.001 0.001" />
      </geometry>
    </collision>
    <inertial>
      <mass value="0.036" />
      <inertia ixx="2.375e-06" ixy="0" ixz="0" iyy="2.375e-06" iyz="0" izz="7.5e-07" />
    </inertial>
  </link>
  <link name="l_left_finger">
    <visual>
      <origin xyz="0.0 -0.05 -0.673001" rpy="0 0 0" />
      <geometry>
        <mesh filename="package://dr_octopus_description/meshes/ee/openarmx_hand/visual/finger.dae" scale="0.001 0.001 0.001" />
      </geometry>
    </visual>
    <collision>
      <origin xyz="0.0 -0.05 -0.673001" rpy="0 0 0" />
      <geometry>
        <mesh filename="package://dr_octopus_description/meshes/ee/openarmx_hand/collision/finger.stl" scale="0.001 0.001 0.001" />
      </geometry>
    </collision>
    <inertial>
      <mass value="0.036" />
      <inertia ixx="2.375e-06" ixy="0" ixz="0" iyy="2.375e-06" iyz="0" izz="7.5e-07" />
    </inertial>
  </link>
  <joint name="l_base_joint" type="fixed">
    <parent link="base_link" />
    <child link="l_link0" />
    <origin xyz="0 0.031 1.2" rpy="-1.5708 0 0" />
  </joint>
  <joint name="l_joint1" type="revolute">
    <parent link="l_link0" />
    <child link="l_link1" />
    <origin xyz="0 0 0.058" rpy="0 0 0" />
    <axis xyz="0 0 1" />
    <limit lower="-3.344396" upper="0.905604" effort="120" velocity="10.47" />
  </joint>
  <joint name="l_joint2" type="revolute">
    <parent link="l_link1" />
    <child link="l_link2" />
    <origin xyz="-0.0205 0 0.081" rpy="-1.5708 0 0" />
    <axis xyz="-1 0 0" />
    <limit lower="-3.2708" upper="0.1292" effort="120" velocity="10.47" />
  </joint>
  <joint name="l_joint3_prime" type="revolute">
    <parent link="l_link2" />
    <child link="l_link3_prime" />
    <origin xyz="0.02 0 0.099" rpy="0 0 0" />
    <axis xyz="0 0 1" />
    <limit lower="-1.57" upper="1.57" effort="60" velocity="10.47" />
  </joint>
  <joint name="l_joint4_prime" type="revolute">
    <parent link="l_link3_prime" />
    <child link="l_link4_prime" />
    <origin xyz="0 0.031002 0.14181" rpy="0 0 0" />
    <axis xyz="0 1 0" />
    <limit lower="0.0" upper="1.8" effort="60" velocity="10.47" />
  </joint>
  <joint name="l_joint3" type="revolute">
    <parent link="l_link4_prime" />
    <child link="l_link3" />
    <origin xyz="-0.02 -0.031 0.082" rpy="0 0 0" />
    <axis xyz="0 0 1" />
    <limit lower="-1.57" upper="1.57" effort="60" velocity="10.47" />
  </joint>
  <joint name="l_joint4" type="revolute">
    <parent link="l_link3" />
    <child link="l_link4" />
    <origin xyz="0 0.031002 0.14181" rpy="0 0 0" />
    <axis xyz="0 1 0" />
    <limit lower="0.0" upper="1.8" effort="60" velocity="10.47" />
  </joint>
  <joint name="l_joint4_ext" type="fixed">
    <parent link="l_link4" />
    <child link="l_link4_ext" />
    <origin xyz="0 -0.065 0" rpy="0 0 0" />
  </joint>
  <joint name="l_joint5" type="revolute">
    <parent link="l_link4" />
    <child link="l_link5" />
    <origin xyz="0 -0.0309 0.126" rpy="0 0 0" />
    <axis xyz="0 0 1" />
    <limit lower="-1.5" upper="1.5" effort="14" velocity="10.47" />
  </joint>
  <joint name="l_joint6" type="revolute">
    <parent link="l_link5" />
    <child link="l_link6" />
    <origin xyz="0.037426 0 0.131" rpy="0 0 0" />
    <axis xyz="1 0 0" />
    <limit lower="-0.75" upper="0.75" effort="14" velocity="10.47" />
  </joint>
  <joint name="l_joint7" type="revolute">
    <parent link="l_link6" />
    <child link="l_link7" />
    <origin xyz="-0.0375 0 0" rpy="0 0 0" />
    <axis xyz="0 -1 0" />
    <limit lower="-1.4" upper="1.4" effort="14" velocity="10.47" />
  </joint>
  <joint name="l_link7_pico_joint" type="fixed">
    <parent link="l_link7" />
    <child link="l_link7_pico" />
    <origin xyz="0 0 0" rpy="0 3.1416 4.7124" />
  </joint>
  <joint name="l_hand_joint" type="fixed">
    <parent link="l_link7" />
    <child link="l_hand" />
    <origin xyz="0 0 0.1001" rpy="0 0 0" />
  </joint>
  <joint name="l_hand_tcp_joint" type="fixed">
    <parent link="l_hand" />
    <child link="l_hand_tcp" />
    <origin xyz="0 0 0.08" rpy="0 0 0" />
  </joint>
  <joint name="l_finger_joint1" type="prismatic">
    <parent link="l_hand" />
    <child link="l_right_finger" />
    <origin xyz="0 -0.006 0.015" rpy="0 0 0" />
    <axis xyz="0 -1 0" />
    <limit lower="0.0" upper="0.044" effort="333" velocity="10.0" />
  </joint>
  <joint name="l_finger_joint2" type="prismatic">
    <parent link="l_hand" />
    <child link="l_left_finger" />
    <origin xyz="0 0.006 0.015" rpy="0 0 0" />
    <axis xyz="0 1 0" />
    <limit lower="0.0" upper="0.044" effort="333" velocity="10.0" />
    <mimic joint="l_finger_joint1" multiplier="1" offset="0" />
  </joint>
</robot>
